Workbook

Sheet Istruzioni
A1: Laboratorio 1 – Iris (Excel 365, IT)
A3: Cosa fare (ordine consigliato)
A4: 1) Dati_grezzi: identifica feature (A:D) e target (species).
A5: 2) Statistiche_guidate: Media/Min/Max per specie sono già pronte. Completa Mediana/Std/Q1/Q3 usando FILTRI di Excel (Filtro per species) e le funzioni dalla barra formule.
A6: 3) Distribuzioni: istogrammi per una feature sepal e una petal (anche per specie).
A7: 4) Scatter: petal length vs petal width con 3 serie (una per specie).
A8: 5) Preprocessing: scegli una feature (B3) e osserva z-score e min-max.
A9: 6) Outlier_IQR: confronta outlier con 1.5×IQR e con |Z|>3.
A10: 7) Consegna: rispondi alle domande e inserisci screenshot dei grafici.

Sheet Dati_grezzi
A1: sepal length (cm) | B1: sepal width (cm) | C1: petal length (cm) | D1: petal width (cm) | E1: species | F1: bin | G1: Contatore | I1: Test T | J1: Colonna di classe
A2: 5.1 | B2: 3.5 | C2: 1.4 | D2: 0.2 | E2: setosa | F2: =IF(Dati_grezzi!C2<=$J$2,"Basso",IF(C2<=$J$3,"Medio","Alto")) -> Basso | G2: 1 | I2: =TTEST(C2:C51,C52:C101,2,3) -> 9.934433e-46 | J2: =_xlfn.PERCENTILE.INC(Dati_grezzi!C2:C151,0.3333) -> 2.62787
A3: 4.9 | B3: 3 | C3: 1.4 | D3: 0.2 | E3: setosa | F3: =IF(Dati_grezzi!C3<=$J$2,"Basso",IF(C3<=$J$3,"Medio","Alto")) -> Basso | G3: 1 | J3: =_xlfn.PERCENTILE.INC(Dati_grezzi!C2:C151,0.66666) -> 4.9
A4: 4.7 | B4: 3.2 | C4: 1.3 | D4: 0.2 | E4: setosa | F4: =IF(Dati_grezzi!C4<=$J$2,"Basso",IF(C4<=$J$3,"Medio","Alto")) -> Basso | G4: 1
A5: 4.6 | B5: 3.1 | C5: 1.5 | D5: 0.2 | E5: setosa | F5: =IF(Dati_grezzi!C5<=$J$2,"Basso",IF(C5<=$J$3,"Medio","Alto")) -> Basso | G5: 1
A6: 5 | B6: 3.6 | C6: 1.4 | D6: 0.2 | E6: setosa | F6: =IF(Dati_grezzi!C6<=$J$2,"Basso",IF(C6<=$J$3,"Medio","Alto")) -> Basso | G6: 1
A7: 5.4 | B7: 3.9 | C7: 1.7 | D7: 0.4 | E7: setosa | F7: =IF(Dati_grezzi!C7<=$J$2,"Basso",IF(C7<=$J$3,"Medio","Alto")) -> Basso | G7: 1
A8: 4.6 | B8: 3.4 | C8: 1.4 | D8: 0.3 | E8: setosa | F8: =IF(Dati_grezzi!C8<=$J$2,"Basso",IF(C8<=$J$3,"Medio","Alto")) -> Basso | G8: 1
A9: 5 | B9: 3.4 | C9: 1.5 | D9: 0.2 | E9: setosa | F9: =IF(Dati_grezzi!C9<=$J$2,"Basso",IF(C9<=$J$3,"Medio","Alto")) -> Basso | G9: 1
A10: 4.4 | B10: 2.9 | C10: 1.4 | D10: 0.2 | E10: setosa | F10: =IF(Dati_grezzi!C10<=$J$2,"Basso",IF(C10<=$J$3,"Medio","Alto")) -> Basso | G10: 1
A11: 4.9 | B11: 3.1 | C11: 1.5 | D11: 0.1 | E11: setosa | F11: =IF(Dati_grezzi!C11<=$J$2,"Basso",IF(C11<=$J$3,"Medio","Alto")) -> Basso | G11: 1
A12: 5.4 | B12: 3.7 | C12: 1.5 | D12: 0.2 | E12: setosa | F12: =IF(Dati_grezzi!C12<=$J$2,"Basso",IF(C12<=$J$3,"Medio","Alto")) -> Basso | G12: 1
A13: 4.8 | B13: 3.4 | C13: 1.6 | D13: 0.2 | E13: setosa | F13: =IF(Dati_grezzi!C13<=$J$2,"Basso",IF(C13<=$J$3,"Medio","Alto")) -> Basso | G13: 1
A14: 4.8 | B14: 3 | C14: 1.4 | D14: 0.1 | E14: setosa | F14: =IF(Dati_grezzi!C14<=$J$2,"Basso",IF(C14<=$J$3,"Medio","Alto")) -> Basso | G14: 1
A15: 4.3 | B15: 3 | C15: 1.1 | D15: 0.1 | E15: setosa | F15: =IF(Dati_grezzi!C15<=$J$2,"Basso",IF(C15<=$J$3,"Medio","Alto")) -> Basso | G15: 1
... A151: 5.9 | B151: 3 | C151: 5.1 | D151: 1.8 | E151: virginica | F151: =IF(Dati_grezzi!C151<=$J$2,"Basso",IF(C151<=$J$3,"Medio","Alto")) -> Alto | G151: 1

Sheet Statistiche_guidate
A1: Feature | B1: Species | C1: Media | D1: Mediana (da calcolare) | E1: Dev.std (da calcolare) | F1: Min | G1: Max | H1: Q1 (da calcolare) | I1: Q3 (da calcolare) | J1: IQR (da calcolare)
A2: sepal length (cm) | B2: setosa | C2: =AVERAGEIF(Dati_grezzi!$E$2:$E$151,"setosa",Dati_grezzi!$A$2:$A$151) -> 5.006 | D2: =MEDIAN(Dati_grezzi!A2:A51) -> 5 | E2: =STDEV(Dati_grezzi!A2:A51) -> 0.35248969 | F2: =_xlfn.MINIFS(Dati_grezzi!$A$2:$A$151,Dati_grezzi!$E$2:$E$151,"setosa") -> 4.3 | G2: =_xlfn.SINGLE(_xlfn.MAXIFS(Dati_grezzi!$A$2:$A$151,Dati_grezzi!$E$2:$E$151,"setosa")) -> 5.8 | H2: =_xlfn.QUARTILE.INC(Dati_grezzi!A2:A51,1) -> 4.8 | I2: =_xlfn.QUARTILE.INC(Dati_grezzi!A2:A51,3) -> 5.2 | J2: =I2-H2 -> 0.4
A3: sepal length (cm) | B3: versicolor | C3: =AVERAGEIF(Dati_grezzi!$E$2:$E$151,"versicolor",Dati_grezzi!$A$2:$A$151) -> 5.936 | F3: =_xlfn.MINIFS(Dati_grezzi!$A$2:$A$151,Dati_grezzi!$E$2:$E$151,"versicolor") -> 4.9 | G3: =_xlfn.SINGLE(_xlfn.MAXIFS(Dati_grezzi!$A$2:$A$151,Dati_grezzi!$E$2:$E$151,"versicolor")) -> 7
A4: sepal length (cm) | B4: virginica | C4: =AVERAGEIF(Dati_grezzi!$E$2:$E$151,"virginica",Dati_grezzi!$A$2:$A$151) -> 6.588 | F4: =_xlfn.MINIFS(Dati_grezzi!$A$2:$A$151,Dati_grezzi!$E$2:$E$151,"virginica") -> 4.9 | G4: =_xlfn.SINGLE(_xlfn.MAXIFS(Dati_grezzi!$A$2:$A$151,Dati_grezzi!$E$2:$E$151,"virginica")) -> 7.9
A5: sepal width (cm) | B5: setosa | C5: =AVERAGEIF(Dati_grezzi!$E$2:$E$151,"setosa",Dati_grezzi!$B$2:$B$151) -> 3.428 | F5: =_xlfn.MINIFS(Dati_grezzi!$B$2:$B$151,Dati_grezzi!$E$2:$E$151,"setosa") -> 2.3 | G5: =_xlfn.SINGLE(_xlfn.MAXIFS(Dati_grezzi!$B$2:$B$151,Dati_grezzi!$E$2:$E$151,"setosa")) -> 4.4
A6: sepal width (cm) | B6: versicolor | C6: =AVERAGEIF(Dati_grezzi!$E$2:$E$151,"versicolor",Dati_grezzi!$B$2:$B$151) -> 2.77 | F6: =_xlfn.MINIFS(Dati_grezzi!$B$2:$B$151,Dati_grezzi!$E$2:$E$151,"versicolor") -> 2 | G6: =_xlfn.SINGLE(_xlfn.MAXIFS(Dati_grezzi!$B$2:$B$151,Dati_grezzi!$E$2:$E$151,"versicolor")) -> 3.4
A7: sepal width (cm) | B7: virginica | C7: =AVERAGEIF(Dati_grezzi!$E$2:$E$151,"virginica",Dati_grezzi!$B$2:$B$151) -> 2.974 | F7: =_xlfn.MINIFS(Dati_grezzi!$B$2:$B$151,Dati_grezzi!$E$2:$E$151,"virginica") -> 2.2 | G7: =_xlfn.SINGLE(_xlfn.MAXIFS(Dati_grezzi!$B$2:$B$151,Dati_grezzi!$E$2:$E$151,"virginica")) -> 3.8
A8: petal length (cm) | B8: setosa | C8: =AVERAGEIF(Dati_grezzi!$E$2:$E$151,"setosa",Dati_grezzi!$C$2:$C$151) -> 1.462 | F8: =_xlfn.MINIFS(Dati_grezzi!$C$2:$C$151,Dati_grezzi!$E$2:$E$151,"setosa") -> 1 | G8: =_xlfn.SINGLE(_xlfn.MAXIFS(Dati_grezzi!$C$2:$C$151,Dati_grezzi!$E$2:$E$151,"setosa")) -> 1.9
A9: petal length (cm) | B9: versicolor | C9: =AVERAGEIF(Dati_grezzi!$E$2:$E$151,"versicolor",Dati_grezzi!$C$2:$C$151) -> 4.26 | F9: =_xlfn.MINIFS(Dati_grezzi!$C$2:$C$151,Dati_grezzi!$E$2:$E$151,"versicolor") -> 3 | G9: =_xlfn.SINGLE(_xlfn.MAXIFS(Dati_grezzi!$C$2:$C$151,Dati_grezzi!$E$2:$E$151,"versicolor")) -> 5.1
A10: petal length (cm) | B10: virginica | C10: =AVERAGEIF(Dati_grezzi!$E$2:$E$151,"virginica",Dati_grezzi!$C$2:$C$151) -> 5.552 | F10: =_xlfn.MINIFS(Dati_grezzi!$C$2:$C$151,Dati_grezzi!$E$2:$E$151,"virginica") -> 4.5 | G10: =_xlfn.SINGLE(_xlfn.MAXIFS(Dati_grezzi!$C$2:$C$151,Dati_grezzi!$E$2:$E$151,"virginica")) -> 6.9
A11: petal width (cm) | B11: setosa | C11: =AVERAGEIF(Dati_grezzi!$E$2:$E$151,"setosa",Dati_grezzi!$D$2:$D$151) -> 0.246 | F11: =_xlfn.SINGLE(_xlfn.MINIFS(Dati_grezzi!$D$2:$D$151,Dati_grezzi!$E$2:$E$151,"setosa")) -> 0.1 | G11: =_xlfn.SINGLE(_xlfn.MAXIFS(Dati_grezzi!$D$2:$D$151,Dati_grezzi!$E$2:$E$151,"setosa")) -> 0.6
A12: petal width (cm) | B12: versicolor | C12: =AVERAGEIF(Dati_grezzi!$E$2:$E$151,"versicolor",Dati_grezzi!$D$2:$D$151) -> 1.326 | F12: =_xlfn.SINGLE(_xlfn.MINIFS(Dati_grezzi!$D$2:$D$151,Dati_grezzi!$E$2:$E$151,"versicolor")) -> 1 | G12: =_xlfn.SINGLE(_xlfn.MAXIFS(Dati_grezzi!$D$2:$D$151,Dati_grezzi!$E$2:$E$151,"versicolor")) -> 1.8
A13: petal width (cm) | B13: virginica | C13: =AVERAGEIF(Dati_grezzi!$E$2:$E$151,"virginica",Dati_grezzi!$D$2:$D$151) -> 2.026 | F13: =_xlfn.SINGLE(_xlfn.MINIFS(Dati_grezzi!$D$2:$D$151,Dati_grezzi!$E$2:$E$151,"virginica")) -> 1.4 | G13: =_xlfn.SINGLE(_xlfn.MAXIFS(Dati_grezzi!$D$2:$D$151,Dati_grezzi!$E$2:$E$151,"virginica")) -> 2.5
A50: Per completare Mediana/Dev.std/Q1/Q3: applica un Filtro su Dati_grezzi per species, poi usa MEDIAN, STDEV.S, QUARTILE.INC su una colonna filtrata (o copia i valori filtrati in una colonna d’appoggio).

Sheet Distribuzioni
A1: Distribuzioni (istogrammi)
A3: Crea istogrammi per una feature sepal e una petal. Poi ripeti per specie.

Sheet Scatter
A1: Scatter plot (da creare in Excel)
A3: Crea uno scatter: x = petal length (cm), y = petal width (cm). Colora per specie (3 serie).

Sheet Preprocessing
A1: Preprocessing su una feature
A3: Feature scelta (scrivi esattamente come in Dati_grezzi): | B3: petal length (cm)
N4: Formula dello z Score: z=(x−μ)/σ ​ | O4: Formula del Min -Max x′=(x−min)/(max−min)​
A5: Valori originali | B5: Z-score | C5: Min-Max [0,1] | E5: Media | F5: Dev.std | G5: Min | H5: Max
A6: =INDEX(Dati_grezzi!$A$2:$D$151,1,MATCH($B$3,Dati_grezzi!$A$1:$D$1,0)) -> 1.4 | B6: =(A6-$E$6)/$F$6 -> -1.3357516 | C6: =(A6-$G$6)/($H$6-$G$6) -> 0.06779661 | E6: =_xlfn.SINGLE(AVERAGE(INDEX(Dati_grezzi!$A$2:$D$151,0,MATCH($B$3,Dati_grezzi!$A$1:$D$1,0)))) -> 3.758 | F6: =_xlfn.SINGLE(_xlfn.STDEV.S(INDEX(Dati_grezzi!$A$2:$D$151,0,MATCH($B$3,Dati_grezzi!$A$1:$D$1,0)))) -> 1.7652982 | G6: =MIN(INDEX(Dati_grezzi!$A$2:$D$151,0,MATCH($B$3,Dati_grezzi!$A$1:$D$1,0))) -> 1 | H6: =MAX(INDEX(Dati_grezzi!$A$2:$D$151,0,MATCH($B$3,Dati_grezzi!$A$1:$D$1,0))) -> 6.9
A7: =INDEX(Dati_grezzi!$A$2:$D$151,2,MATCH($B$3,Dati_grezzi!$A$1:$D$1,0)) -> 1.4 | B7: =(A7-$E$6)/$F$6 -> -1.3357516 | C7: =(A7-$G$6)/($H$6-$G$6) -> 0.06779661
A8: =INDEX(Dati_grezzi!$A$2:$D$151,3,MATCH($B$3,Dati_grezzi!$A$1:$D$1,0)) -> 1.3 | B8: =(A8-$E$6)/$F$6 -> -1.3923993 | C8: =(A8-$G$6)/($H$6-$G$6) -> 0.050847458
A9: =INDEX(Dati_grezzi!$A$2:$D$151,4,MATCH($B$3,Dati_grezzi!$A$1:$D$1,0)) -> 1.5 | B9: =(A9-$E$6)/$F$6 -> -1.279104 | C9: =(A9-$G$6)/($H$6-$G$6) -> 0.084745763
A10: =INDEX(Dati_grezzi!$A$2:$D$151,5,MATCH($B$3,Dati_grezzi!$A$1:$D$1,0)) -> 1.4 | B10: =(A10-$E$6)/$F$6 -> -1.3357516 | C10: =(A10-$G$6)/($H$6-$G$6) -> 0.06779661
A11: =INDEX(Dati_grezzi!$A$2:$D$151,6,MATCH($B$3,Dati_grezzi!$A$1:$D$1,0)) -> 1.7 | B11: =(A11-$E$6)/$F$6 -> -1.1658087 | C11: =(A11-$G$6)/($H$6-$G$6) -> 0.11864407
A12: =INDEX(Dati_grezzi!$A$2:$D$151,7,MATCH($B$3,Dati_grezzi!$A$1:$D$1,0)) -> 1.4 | B12: =(A12-$E$6)/$F$6 -> -1.3357516 | C12: =(A12-$G$6)/($H$6-$G$6) -> 0.06779661
A13: =INDEX(Dati_grezzi!$A$2:$D$151,8,MATCH($B$3,Dati_grezzi!$A$1:$D$1,0)) -> 1.5 | B13: =(A13-$E$6)/$F$6 -> -1.279104 | C13: =(A13-$G$6)/($H$6-$G$6) -> 0.084745763
A14: =INDEX(Dati_grezzi!$A$2:$D$151,9,MATCH($B$3,Dati_grezzi!$A$1:$D$1,0)) -> 1.4 | B14: =(A14-$E$6)/$F$6 -> -1.3357516 | C14: =(A14-$G$6)/($H$6-$G$6) -> 0.06779661
A15: =INDEX(Dati_grezzi!$A$2:$D$151,10,MATCH($B$3,Dati_grezzi!$A$1:$D$1,0)) -> 1.5 | B15: =(A15-$E$6)/$F$6 -> -1.279104 | C15: =(A15-$G$6)/($H$6-$G$6) -> 0.084745763
A16: =INDEX(Dati_grezzi!$A$2:$D$151,11,MATCH($B$3,Dati_grezzi!$A$1:$D$1,0)) -> 1.5 | B16: =(A16-$E$6)/$F$6 -> -1.279104 | C16: =(A16-$G$6)/($H$6-$G$6) -> 0.084745763
A17: =INDEX(Dati_grezzi!$A$2:$D$151,12,MATCH($B$3,Dati_grezzi!$A$1:$D$1,0)) -> 1.6 | B17: =(A17-$E$6)/$F$6 -> -1.2224563 | C17: =(A17-$G$6)/($H$6-$G$6) -> 0.10169492
A18: =INDEX(Dati_grezzi!$A$2:$D$151,13,MATCH($B$3,Dati_grezzi!$A$1:$D$1,0)) -> 1.4 | B18: =(A18-$E$6)/$F$6 -> -1.3357516 | C18: =(A18-$G$6)/($H$6-$G$6) -> 0.06779661
A19: =INDEX(Dati_grezzi!$A$2:$D$151,14,MATCH($B$3,Dati_grezzi!$A$1:$D$1,0)) -> 1.1 | B19: =(A19-$E$6)/$F$6 -> -1.5056946 | C19: =(A19-$G$6)/($H$6-$G$6) -> 0.016949153
A20: =INDEX(Dati_grezzi!$A$2:$D$151,15,MATCH($B$3,Dati_grezzi!$A$1:$D$1,0)) -> 1.2 | B20: =(A20-$E$6)/$F$6 -> -1.4490469 | C20: =(A20-$G$6)/($H$6-$G$6) -> 0.033898305
A21: =INDEX(Dati_grezzi!$A$2:$D$151,16,MATCH($B$3,Dati_grezzi!$A$1:$D$1,0)) -> 1.5 | B21: =(A21-$E$6)/$F$6 -> -1.279104 | C21: =(A21-$G$6)/($H$6-$G$6) -> 0.084745763
A22: =INDEX(Dati_grezzi!$A$2:$D$151,17,MATCH($B$3,Dati_grezzi!$A$1:$D$1,0)) -> 1.3 | B22: =(A22-$E$6)/$F$6 -> -1.3923993 | C22: =(A22-$G$6)/($H$6-$G$6) -> 0.050847458
A23: =INDEX(Dati_grezzi!$A$2:$D$151,18,MATCH($B$3,Dati_grezzi!$A$1:$D$1,0)) -> 1.4 | B23: =(A23-$E$6)/$F$6 -> -1.3357516 | C23: =(A23-$G$6)/($H$6-$G$6) -> 0.06779661
A24: =INDEX(Dati_grezzi!$A$2:$D$151,19,MATCH($B$3,Dati_grezzi!$A$1:$D$1,0)) -> 1.7 | B24: =(A24-$E$6)/$F$6 -> -1.1658087 | C24: =(A24-$G$6)/($H$6-$G$6) -> 0.11864407
A25: =INDEX(Dati_grezzi!$A$2:$D$151,20,MATCH($B$3,Dati_grezzi!$A$1:$D$1,0)) -> 1.5 | B25: =(A25-$E$6)/$F$6 -> -1.279104 | C25: =(A25-$G$6)/($H$6-$G$6) -> 0.084745763
A26: =INDEX(Dati_grezzi!$A$2:$D$151,21,MATCH($B$3,Dati_grezzi!$A$1:$D$1,0)) -> 1.7 | B26: =(A26-$E$6)/$F$6 -> -1.1658087 | C26: =(A26-$G$6)/($H$6-$G$6) -> 0.11864407
A27: =INDEX(Dati_grezzi!$A$2:$D$151,22,MATCH($B$3,Dati_grezzi!$A$1:$D$1,0)) -> 1.5 | B27: =(A27-$E$6)/$F$6 -> -1.279104 | C27: =(A27-$G$6)/($H$6-$G$6) -> 0.084745763
A28: =INDEX(Dati_grezzi!$A$2:$D$151,23,MATCH($B$3,Dati_grezzi!$A$1:$D$1,0)) -> 1 | B28: =(A28-$E$6)/$F$6 -> -1.5623422 | C28: =(A28-$G$6)/($H$6-$G$6) -> 0
A29: =INDEX(Dati_grezzi!$A$2:$D$151,24,MATCH($B$3,Dati_grezzi!$A$1:$D$1,0)) -> 1.7 | B29: =(A29-$E$6)/$F$6 -> -1.1658087 | C29: =(A29-$G$6)/($H$6-$G$6) -> 0.11864407
A30: =INDEX(Dati_grezzi!$A$2:$D$151,25,MATCH($B$3,Dati_grezzi!$A$1:$D$1,0)) -> 1.9 | B30: =(A30-$E$6)/$F$6 -> -1.0525134 | C30: =(A30-$G$6)/($H$6-$G$6) -> 0.15254237
A31: =INDEX(Dati_grezzi!$A$2:$D$151,26,MATCH($B$3,Dati_grezzi!$A$1:$D$1,0)) -> 1.6 | B31: =(A31-$E$6)/$F$6 -> -1.2224563 | C31: =(A31-$G$6)/($H$6-$G$6) -> 0.10169492
A32: =INDEX(Dati_grezzi!$A$2:$D$151,27,MATCH($B$3,Dati_grezzi!$A$1:$D$1,0)) -> 1.6 | B32: =(A32-$E$6)/$F$6 -> -1.2224563 | C32: =(A32-$G$6)/($H$6-$G$6) -> 0.10169492
A33: =INDEX(Dati_grezzi!$A$2:$D$151,28,MATCH($B$3,Dati_grezzi!$A$1:$D$1,0)) -> 1.5 | B33: =(A33-$E$6)/$F$6 -> -1.279104 | C33: =(A33-$G$6)/($H$6-$G$6) -> 0.084745763
A34: =INDEX(Dati_grezzi!$A$2:$D$151,29,MATCH($B$3,Dati_grezzi!$A$1:$D$1,0)) -> 1.4 | B34: =(A34-$E$6)/$F$6 -> -1.3357516 | C34: =(A34-$G$6)/($H$6-$G$6) -> 0.06779661
A35: =INDEX(Dati_grezzi!$A$2:$D$151,30,MATCH($B$3,Dati_grezzi!$A$1:$D$1,0)) -> 1.6 | B35: =(A35-$E$6)/$F$6 -> -1.2224563 | C35: =(A35-$G$6)/($H$6-$G$6) -> 0.10169492
A36: =INDEX(Dati_grezzi!$A$2:$D$151,31,MATCH($B$3,Dati_grezzi!$A$1:$D$1,0)) -> 1.6 | B36: =(A36-$E$6)/$F$6 -> -1.2224563 | C36: =(A36-$G$6)/($H$6-$G$6) -> 0.10169492
A37: =INDEX(Dati_grezzi!$A$2:$D$151,32,MATCH($B$3,Dati_grezzi!$A$1:$D$1,0)) -> 1.5 | B37: =(A37-$E$6)/$F$6 -> -1.279104 | C37: =(A37-$G$6)/($H$6-$G$6) -> 0.084745763
A38: =INDEX(Dati_grezzi!$A$2:$D$151,33,MATCH($B$3,Dati_grezzi!$A$1:$D$1,0)) -> 1.5 | B38: =(A38-$E$6)/$F$6 -> -1.279104 | C38: =(A38-$G$6)/($H$6-$G$6) -> 0.084745763
A39: =INDEX(Dati_grezzi!$A$2:$D$151,34,MATCH($B$3,Dati_grezzi!$A$1:$D$1,0)) -> 1.4 | B39: =(A39-$E$6)/$F$6 -> -1.3357516 | C39: =(A39-$G$6)/($H$6-$G$6) -> 0.06779661
A40: =INDEX(Dati_grezzi!$A$2:$D$151,35,MATCH($B$3,Dati_grezzi!$A$1:$D$1,0)) -> 1.5 | B40: =(A40-$E$6)/$F$6 -> -1.279104 | C40: =(A40-$G$6)/($H$6-$G$6) -> 0.084745763
A41: =INDEX(Dati_grezzi!$A$2:$D$151,36,MATCH($B$3,Dati_grezzi!$A$1:$D$1,0)) -> 1.2 | B41: =(A41-$E$6)/$F$6 -> -1.4490469 | C41: =(A41-$G$6)/($H$6-$G$6) -> 0.033898305
...

Sheet Outlier_IQR
A1: Outlier: 1.5×IQR vs |Z|>3
A3: Feature scelta: | B3: sepal length (cm)
A4: Valore | B4: Q1 | C4: Q3 | D4: IQR | E4: Lower | F4: Upper | G4: Outlier_IQR? | H4: Z-score | I4: |Z|>3?
A5: =INDEX(Dati_grezzi!$A$2:$D$151,1,MATCH($B$3,Dati_grezzi!$A$1:$D$1,0)) -> 5.1 | B5: =_xlfn.SINGLE(_xlfn.QUARTILE.INC(INDEX(Dati_grezzi!$A$2:$D$151,0,MATCH($B$3,Dati_grezzi!$A$1:$D$1,0)),1)) -> 5.1 | C5: =_xlfn.SINGLE(_xlfn.QUARTILE.INC(INDEX(Dati_grezzi!$A$2:$D$151,0,MATCH($B$3,Dati_grezzi!$A$1:$D$1,0)),3)) -> 6.4 | D5: =C5-B5 -> 1.3 | E5: =B5-1.5*D5 -> 3.15 | F5: =C5+1.5*D5 -> 8.35 | G5: =IF(OR(A5<$E$5,A5>$F$5),"YES","NO") -> NO | H5: =(A5-AVERAGE(INDEX(Dati_grezzi!$A$2:$D$151,0,MATCH($B$3,Dati_grezzi!$A$1:$D$1,0))))/_xlfn.SINGLE(STDEV(INDEX(Dati_grezzi!$A$2:$D$151,0,MATCH($B$3,Dati_grezzi!$A$1:$D$1,0)))) -> -0.89767388 | I5: =IF(ABS(H5)>3,"YES","NO") -> NO
A6: =INDEX(Dati_grezzi!$A$2:$D$151,2,MATCH($B$3,Dati_grezzi!$A$1:$D$1,0)) -> 4.9 | G6: =IF(OR(A6<$E$5,A6>$F$5),"YES","NO") -> NO | H6: =(A6-AVERAGE(INDEX(Dati_grezzi!$A$2:$D$151,0,MATCH($B$3,Dati_grezzi!$A$1:$D$1,0))))/_xlfn.SINGLE(STDEV(INDEX(Dati_grezzi!$A$2:$D$151,0,MATCH($B$3,Dati_grezzi!$A$1:$D$1,0)))) -> -1.1392005 | I6: =IF(ABS(H6)>3,"YES","NO") -> NO
A7: =INDEX(Dati_grezzi!$A$2:$D$151,3,MATCH($B$3,Dati_grezzi!$A$1:$D$1,0)) -> 4.7 | G7: =IF(OR(A7<$E$5,A7>$F$5),"YES","NO") -> NO | H7: =(A7-AVERAGE(INDEX(Dati_grezzi!$A$2:$D$151,0,MATCH($B$3,Dati_grezzi!$A$1:$D$1,0))))/_xlfn.SINGLE(STDEV(INDEX(Dati_grezzi!$A$2:$D$151,0,MATCH($B$3,Dati_grezzi!$A$1:$D$1,0)))) -> -1.3807271 | I7: =IF(ABS(H7)>3,"YES","NO") -> NO
A8: =INDEX(Dati_grezzi!$A$2:$D$151,4,MATCH($B$3,Dati_grezzi!$A$1:$D$1,0)) -> 4.6 | G8: =IF(OR(A8<$E$5,A8>$F$5),"YES","NO") -> NO | H8: =(A8-AVERAGE(INDEX(Dati_grezzi!$A$2:$D$151,0,MATCH($B$3,Dati_grezzi!$A$1:$D$1,0))))/_xlfn.SINGLE(STDEV(INDEX(Dati_grezzi!$A$2:$D$151,0,MATCH($B$3,Dati_grezzi!$A$1:$D$1,0)))) -> -1.5014904 | I8: =IF(ABS(H8)>3,"YES","NO") -> NO
A9: =INDEX(Dati_grezzi!$A$2:$D$151,5,MATCH($B$3,Dati_grezzi!$A$1:$D$1,0)) -> 5 | G9: =IF(OR(A9<$E$5,A9>$F$5),"YES","NO") -> NO | H9: =(A9-AVERAGE(INDEX(Dati_grezzi!$A$2:$D$151,0,MATCH($B$3,Dati_grezzi!$A$1:$D$1,0))))/_xlfn.SINGLE(STDEV(INDEX(Dati_grezzi!$A$2:$D$151,0,MATCH($B$3,Dati_grezzi!$A$1:$D$1,0)))) -> -1.0184372 | I9: =IF(ABS(H9)>3,"YES","NO") -> NO
A10: =INDEX(Dati_grezzi!$A$2:$D$151,6,MATCH($B$3,Dati_grezzi!$A$1:$D$1,0)) -> 5.4 | G10: =IF(OR(A10<$E$5,A10>$F$5),"YES","NO") -> NO | H10: =(A10-AVERAGE(INDEX(Dati_grezzi!$A$2:$D$151,0,MATCH($B$3,Dati_grezzi!$A$1:$D$1,0))))/_xlfn.SINGLE(STDEV(INDEX(Dati_grezzi!$A$2:$D$151,0,MATCH($B$3,Dati_grezzi!$A$1:$D$1,0)))) -> -0.53538397 | I10: =IF(ABS(H10)>3,"YES","NO") -> NO
A11: =INDEX(Dati_grezzi!$A$2:$D$151,7,MATCH($B$3,Dati_grezzi!$A$1:$D$1,0)) -> 4.6 | G11: =IF(OR(A11<$E$5,A11>$F$5),"YES","NO") -> NO | H11: =(A11-AVERAGE(INDEX(Dati_grezzi!$A$2:$D$151,0,MATCH($B$3,Dati_grezzi!$A$1:$D$1,0))))/_xlfn.SINGLE(STDEV(INDEX(Dati_grezzi!$A$2:$D$151,0,MATCH($B$3,Dati_grezzi!$A$1:$D$1,0)))) -> -1.5014904 | I11: =IF(ABS(H11)>3,"YES","NO") -> NO
A12: =INDEX(Dati_grezzi!$A$2:$D$151,8,MATCH($B$3,Dati_grezzi!$A$1:$D$1,0)) -> 5 | G12: =IF(OR(A12<$E$5,A12>$F$5),"YES","NO") -> NO | H12: =(A12-AVERAGE(INDEX(Dati_grezzi!$A$2:$D$151,0,MATCH($B$3,Dati_grezzi!$A$1:$D$1,0))))/_xlfn.SINGLE(STDEV(INDEX(Dati_grezzi!$A$2:$D$151,0,MATCH($B$3,Dati_grezzi!$A$1:$D$1,0)))) -> -1.0184372 | I12: =IF(ABS(H12)>3,"YES","NO") -> NO
A13: =INDEX(Dati_grezzi!$A$2:$D$151,9,MATCH($B$3,Dati_grezzi!$A$1:$D$1,0)) -> 4.4 | G13: =IF(OR(A13<$E$5,A13>$F$5),"YES","NO") -> NO | H13: =(A13-AVERAGE(INDEX(Dati_grezzi!$A$2:$D$151,0,MATCH($B$3,Dati_grezzi!$A$1:$D$1,0))))/_xlfn.SINGLE(STDEV(INDEX(Dati_grezzi!$A$2:$D$151,0,MATCH($B$3,Dati_grezzi!$A$1:$D$1,0)))) -> -1.743017 | I13: =IF(ABS(H13)>3,"YES","NO") -> NO
A14: =INDEX(Dati_grezzi!$A$2:$D$151,10,MATCH($B$3,Dati_grezzi!$A$1:$D$1,0)) -> 4.9 | G14: =IF(OR(A14<$E$5,A14>$F$5),"YES","NO") -> NO | H14: =(A14-AVERAGE(INDEX(Dati_grezzi!$A$2:$D$151,0,MATCH($B$3,Dati_grezzi!$A$1:$D$1,0))))/_xlfn.SINGLE(STDEV(INDEX(Dati_grezzi!$A$2:$D$151,0,MATCH($B$3,Dati_grezzi!$A$1:$D$1,0)))) -> -1.1392005 | I14: =IF(ABS(H14)>3,"YES","NO") -> NO
A15: =INDEX(Dati_grezzi!$A$2:$D$151,11,MATCH($B$3,Dati_grezzi!$A$1:$D$1,0)) -> 5.4 | G15: =IF(OR(A15<$E$5,A15>$F$5),"YES","NO") -> NO | H15: =(A15-AVERAGE(INDEX(Dati_grezzi!$A$2:$D$151,0,MATCH($B$3,Dati_grezzi!$A$1:$D$1,0))))/_xlfn.SINGLE(STDEV(INDEX(Dati_grezzi!$A$2:$D$151,0,MATCH($B$3,Dati_grezzi!$A$1:$D$1,0)))) -> -0.53538397 | I15: =IF(ABS(H15)>3,"YES","NO") -> NO
A16: =INDEX(Dati_grezzi!$A$2:$D$151,12,MATCH($B$3,Dati_grezzi!$A$1:$D$1,0)) -> 4.8 | G16: =IF(OR(A16<$E$5,A16>$F$5),"YES","NO") -> NO | H16: =(A16-AVERAGE(INDEX(Dati_grezzi!$A$2:$D$151,0,MATCH($B$3,Dati_grezzi!$A$1:$D$1,0))))/_xlfn.SINGLE(STDEV(INDEX(Dati_grezzi!$A$2:$D$151,0,MATCH($B$3,Dati_grezzi!$A$1:$D$1,0)))) -> -1.2599638 | I16: =IF(ABS(H16)>3,"YES","NO") -> NO
A17: =INDEX(Dati_grezzi!$A$2:$D$151,13,MATCH($B$3,Dati_grezzi!$A$1:$D$1,0)) -> 4.8 | G17: =IF(OR(A17<$E$5,A17>$F$5),"YES","NO") -> NO | H17: =(A17-AVERAGE(INDEX(Dati_grezzi!$A$2:$D$151,0,MATCH($B$3,Dati_grezzi!$A$1:$D$1,0))))/_xlfn.SINGLE(STDEV(INDEX(Dati_grezzi!$A$2:$D$151,0,MATCH($B$3,Dati_grezzi!$A$1:$D$1,0)))) -> -1.2599638 | I17: =IF(ABS(H17)>3,"YES","NO") -> NO
A18: =INDEX(Dati_grezzi!$A$2:$D$151,14,MATCH($B$3,Dati_grezzi!$A$1:$D$1,0)) -> 4.3 | G18: =IF(OR(A18<$E$5,A18>$F$5),"YES","NO") -> NO | H18: =(A18-AVERAGE(INDEX(Dati_grezzi!$A$2:$D$151,0,MATCH($B$3,Dati_grezzi!$A$1:$D$1,0))))/_xlfn.SINGLE(STDEV(INDEX(Dati_grezzi!$A$2:$D$151,0,MATCH($B$3,Dati_grezzi!$A$1:$D$1,0)))) -> -1.8637803 | I18: =IF(ABS(H18)>3,"YES","NO") -> NO
A19: =INDEX(Dati_grezzi!$A$2:$D$151,15,MATCH($B$3,Dati_grezzi!$A$1:$D$1,0)) -> 5.8 | G19: =IF(OR(A19<$E$5,A19>$F$5),"YES","NO") -> NO | H19: =(A19-AVERAGE(INDEX(Dati_grezzi!$A$2:$D$151,0,MATCH($B$3,Dati_grezzi!$A$1:$D$1,0))))/_xlfn.SINGLE(STDEV(INDEX(Dati_grezzi!$A$2:$D$151,0,MATCH($B$3,Dati_grezzi!$A$1:$D$1,0)))) -> -0.052330764 | I19: =IF(ABS(H19)>3,"YES","NO") -> NO
A20: =INDEX(Dati_grezzi!$A$2:$D$151,16,MATCH($B$3,Dati_grezzi!$A$1:$D$1,0)) -> 5.7 | G20: =IF(OR(A20<$E$5,A20>$F$5),"YES","NO") -> NO | H20: =(A20-AVERAGE(INDEX(Dati_grezzi!$A$2:$D$151,0,MATCH($B$3,Dati_grezzi!$A$1:$D$1,0))))/_xlfn.SINGLE(STDEV(INDEX(Dati_grezzi!$A$2:$D$151,0,MATCH($B$3,Dati_grezzi!$A$1:$D$1,0)))) -> -0.17309407 | I20: =IF(ABS(H20)>3,"YES","NO") -> NO
A21: =INDEX(Dati_grezzi!$A$2:$D$151,17,MATCH($B$3,Dati_grezzi!$A$1:$D$1,0)) -> 5.4 | G21: =IF(OR(A21<$E$5,A21>$F$5),"YES","NO") -> NO | H21: =(A21-AVERAGE(INDEX(Dati_grezzi!$A$2:$D$151,0,MATCH($B$3,Dati_grezzi!$A$1:$D$1,0))))/_xlfn.SINGLE(STDEV(INDEX(Dati_grezzi!$A$2:$D$151,0,MATCH($B$3,Dati_grezzi!$A$1:$D$1,0)))) -> -0.53538397 | I21: =IF(ABS(H21)>3,"YES","NO") -> NO
A22: =INDEX(Dati_grezzi!$A$2:$D$151,18,MATCH($B$3,Dati_grezzi!$A$1:$D$1,0)) -> 5.1 | G22: =IF(OR(A22<$E$5,A22>$F$5),"YES","NO") -> NO | H22: =(A22-AVERAGE(INDEX(Dati_grezzi!$A$2:$D$151,0,MATCH($B$3,Dati_grezzi!$A$1:$D$1,0))))/_xlfn.SINGLE(STDEV(INDEX(Dati_grezzi!$A$2:$D$151,0,MATCH($B$3,Dati_grezzi!$A$1:$D$1,0)))) -> -0.89767388 | I22: =IF(ABS(H22)>3,"YES","NO") -> NO
A23: =INDEX(Dati_grezzi!$A$2:$D$151,19,MATCH($B$3,Dati_grezzi!$A$1:$D$1,0)) -> 5.7 | G23: =IF(OR(A23<$E$5,A23>$F$5),"YES","NO") -> NO | H23: =(A23-AVERAGE(INDEX(Dati_grezzi!$A$2:$D$151,0,MATCH($B$3,Dati_grezzi!$A$1:$D$1,0))))/_xlfn.SINGLE(STDEV(INDEX(Dati_grezzi!$A$2:$D$151,0,MATCH($B$3,Dati_grezzi!$A$1:$D$1,0)))) -> -0.17309407 | I23: =IF(ABS(H23)>3,"YES","NO") -> NO
A24: =INDEX(Dati_grezzi!$A$2:$D$151,20,MATCH($B$3,Dati_grezzi!$A$1:$D$1,0)) -> 5.1 | G24: =IF(OR(A24<$E$5,A24>$F$5),"YES","NO") -> NO | H24: =(A24-AVERAGE(INDEX(Dati_grezzi!$A$2:$D$151,0,MATCH($B$3,Dati_grezzi!$A$1:$D$1,0))))/_xlfn.SINGLE(STDEV(INDEX(Dati_grezzi!$A$2:$D$151,0,MATCH($B$3,Dati_grezzi!$A$1:$D$1,0)))) -> -0.89767388 | I24: =IF(ABS(H24)>3,"YES","NO") -> NO
A25: =INDEX(Dati_grezzi!$A$2:$D$151,21,MATCH($B$3,Dati_grezzi!$A$1:$D$1,0)) -> 5.4 | G25: =IF(OR(A25<$E$5,A25>$F$5),"YES","NO") -> NO | H25: =(A25-AVERAGE(INDEX(Dati_grezzi!$A$2:$D$151,0,MATCH($B$3,Dati_grezzi!$A$1:$D$1,0))))/_xlfn.SINGLE(STDEV(INDEX(Dati_grezzi!$A$2:$D$151,0,MATCH($B$3,Dati_grezzi!$A$1:$D$1,0)))) -> -0.53538397 | I25: =IF(ABS(H25)>3,"YES","NO") -> NO
A26: =INDEX(Dati_grezzi!$A$2:$D$151,22,MATCH($B$3,Dati_grezzi!$A$1:$D$1,0)) -> 5.1 | G26: =IF(OR(A26<$E$5,A26>$F$5),"YES","NO") -> NO | H26: =(A26-AVERAGE(INDEX(Dati_grezzi!$A$2:$D$151,0,MATCH($B$3,Dati_grezzi!$A$1:$D$1,0))))/_xlfn.SINGLE(STDEV(INDEX(Dati_grezzi!$A$2:$D$151,0,MATCH($B$3,Dati_grezzi!$A$1:$D$1,0)))) -> -0.89767388 | I26: =IF(ABS(H26)>3,"YES","NO") -> NO
A27: =INDEX(Dati_grezzi!$A$2:$D$151,23,MATCH($B$3,Dati_grezzi!$A$1:$D$1,0)) -> 4.6 | G27: =IF(OR(A27<$E$5,A27>$F$5),"YES","NO") -> NO | H27: =(A27-AVERAGE(INDEX(Dati_grezzi!$A$2:$D$151,0,MATCH($B$3,Dati_grezzi!$A$1:$D$1,0))))/_xlfn.SINGLE(STDEV(INDEX(Dati_grezzi!$A$2:$D$151,0,MATCH($B$3,Dati_grezzi!$A$1:$D$1,0)))) -> -1.5014904 | I27: =IF(ABS(H27)>3,"YES","NO") -> NO
A28: =INDEX(Dati_grezzi!$A$2:$D$151,24,MATCH($B$3,Dati_grezzi!$A$1:$D$1,0)) -> 5.1 | G28: =IF(OR(A28<$E$5,A28>$F$5),"YES","NO") -> NO | H28: =(A28-AVERAGE(INDEX(Dati_grezzi!$A$2:$D$151,0,MATCH($B$3,Dati_grezzi!$A$1:$D$1,0))))/_xlfn.SINGLE(STDEV(INDEX(Dati_grezzi!$A$2:$D$151,0,MATCH($B$3,Dati_grezzi!$A$1:$D$1,0)))) -> -0.89767388 | I28: =IF(ABS(H28)>3,"YES","NO") -> NO
A29: =INDEX(Dati_grezzi!$A$2:$D$151,25,MATCH($B$3,Dati_grezzi!$A$1:$D$1,0)) -> 4.8 | G29: =IF(OR(A29<$E$5,A29>$F$5),"YES","NO") -> NO | H29: =(A29-AVERAGE(INDEX(Dati_grezzi!$A$2:$D$151,0,MATCH($B$3,Dati_grezzi!$A$1:$D$1,0))))/_xlfn.SINGLE(STDEV(INDEX(Dati_grezzi!$A$2:$D$151,0,MATCH($B$3,Dati_grezzi!$A$1:$D$1,0)))) -> -1.2599638 | I29: =IF(ABS(H29)>3,"YES","NO") -> NO
A30: =INDEX(Dati_grezzi!$A$2:$D$151,26,MATCH($B$3,Dati_grezzi!$A$1:$D$1,0)) -> 5 | G30: =IF(OR(A30<$E$5,A30>$F$5),"YES","NO") -> NO | H30: =(A30-AVERAGE(INDEX(Dati_grezzi!$A$2:$D$151,0,MATCH($B$3,Dati_grezzi!$A$1:$D$1,0))))/_xlfn.SINGLE(STDEV(INDEX(Dati_grezzi!$A$2:$D$151,0,MATCH($B$3,Dati_grezzi!$A$1:$D$1,0)))) -> -1.0184372 | I30: =IF(ABS(H30)>3,"YES","NO") -> NO
A31: =INDEX(Dati_grezzi!$A$2:$D$151,27,MATCH($B$3,Dati_grezzi!$A$1:$D$1,0)) -> 5 | G31: =IF(OR(A31<$E$5,A31>$F$5),"YES","NO") -> NO | H31: =(A31-AVERAGE(INDEX(Dati_grezzi!$A$2:$D$151,0,MATCH($B$3,Dati_grezzi!$A$1:$D$1,0))))/_xlfn.SINGLE(STDEV(INDEX(Dati_grezzi!$A$2:$D$151,0,MATCH($B$3,Dati_grezzi!$A$1:$D$1,0)))) -> -1.0184372 | I31: =IF(ABS(H31)>3,"YES","NO") -> NO
A32: =INDEX(Dati_grezzi!$A$2:$D$151,28,MATCH($B$3,Dati_grezzi!$A$1:$D$1,0)) -> 5.2 | G32: =IF(OR(A32<$E$5,A32>$F$5),"YES","NO") -> NO | H32: =(A32-AVERAGE(INDEX(Dati_grezzi!$A$2:$D$151,0,MATCH($B$3,Dati_grezzi!$A$1:$D$1,0))))/_xlfn.SINGLE(STDEV(INDEX(Dati_grezzi!$A$2:$D$151,0,MATCH($B$3,Dati_grezzi!$A$1:$D$1,0)))) -> -0.77691058 | I32: =IF(ABS(H32)>3,"YES","NO") -> NO
A33: =INDEX(Dati_grezzi!$A$2:$D$151,29,MATCH($B$3,Dati_grezzi!$A$1:$D$1,0)) -> 5.2 | G33: =IF(OR(A33<$E$5,A33>$F$5),"YES","NO") -> NO | H33: =(A33-AVERAGE(INDEX(Dati_grezzi!$A$2:$D$151,0,MATCH($B$3,Dati_grezzi!$A$1:$D$1,0))))/_xlfn.SINGLE(STDEV(INDEX(Dati_grezzi!$A$2:$D$151,0,MATCH($B$3,Dati_grezzi!$A$1:$D$1,0)))) -> -0.77691058 | I33: =IF(ABS(H33)>3,"YES","NO") -> NO
A34: =INDEX(Dati_grezzi!$A$2:$D$151,30,MATCH($B$3,Dati_grezzi!$A$1:$D$1,0)) -> 4.7 | G34: =IF(OR(A34<$E$5,A34>$F$5),"YES","NO") -> NO | H34: =(A34-AVERAGE(INDEX(Dati_grezzi!$A$2:$D$151,0,MATCH($B$3,Dati_grezzi!$A$1:$D$1,0))))/_xlfn.SINGLE(STDEV(INDEX(Dati_grezzi!$A$2:$D$151,0,MATCH($B$3,Dati_grezzi!$A$1:$D$1,0)))) -> -1.3807271 | I34: =IF(ABS(H34)>3,"YES","NO") -> NO
A35: =INDEX(Dati_grezzi!$A$2:$D$151,31,MATCH($B$3,Dati_grezzi!$A$1:$D$1,0)) -> 4.8 | G35: =IF(OR(A35<$E$5,A35>$F$5),"YES","NO") -> NO | H35: =(A35-AVERAGE(INDEX(Dati_grezzi!$A$2:$D$151,0,MATCH($B$3,Dati_grezzi!$A$1:$D$1,0))))/_xlfn.SINGLE(STDEV(INDEX(Dati_grezzi!$A$2:$D$151,0,MATCH($B$3,Dati_grezzi!$A$1:$D$1,0)))) -> -1.2599638 | I35: =IF(ABS(H35)>3,"YES","NO") -> NO
A36: =INDEX(Dati_grezzi!$A$2:$D$151,32,MATCH($B$3,Dati_grezzi!$A$1:$D$1,0)) -> 5.4 | G36: =IF(OR(A36<$E$5,A36>$F$5),"YES","NO") -> NO | H36: =(A36-AVERAGE(INDEX(Dati_grezzi!$A$2:$D$151,0,MATCH($B$3,Dati_grezzi!$A$1:$D$1,0))))/_xlfn.SINGLE(STDEV(INDEX(Dati_grezzi!$A$2:$D$151,0,MATCH($B$3,Dati_grezzi!$A$1:$D$1,0)))) -> -0.53538397 | I36: =IF(ABS(H36)>3,"YES","NO") -> NO
A37: =INDEX(Dati_grezzi!$A$2:$D$151,33,MATCH($B$3,Dati_grezzi!$A$1:$D$1,0)) -> 5.2 | G37: =IF(OR(A37<$E$5,A37>$F$5),"YES","NO") -> NO | H37: =(A37-AVERAGE(INDEX(Dati_grezzi!$A$2:$D$151,0,MATCH($B$3,Dati_grezzi!$A$1:$D$1,0))))/_xlfn.SINGLE(STDEV(INDEX(Dati_grezzi!$A$2:$D$151,0,MATCH($B$3,Dati_grezzi!$A$1:$D$1,0)))) -> -0.77691058 | I37: =IF(ABS(H37)>3,"YES","NO") -> NO
A38: =INDEX(Dati_grezzi!$A$2:$D$151,34,MATCH($B$3,Dati_grezzi!$A$1:$D$1,0)) -> 5.5 | G38: =IF(OR(A38<$E$5,A38>$F$5),"YES","NO") -> NO | H38: =(A38-AVERAGE(INDEX(Dati_grezzi!$A$2:$D$151,0,MATCH($B$3,Dati_grezzi!$A$1:$D$1,0))))/_xlfn.SINGLE(STDEV(INDEX(Dati_grezzi!$A$2:$D$151,0,MATCH($B$3,Dati_grezzi!$A$1:$D$1,0)))) -> -0.41462067 | I38: =IF(ABS(H38)>3,"YES","NO") -> NO
A39: =INDEX(Dati_grezzi!$A$2:$D$151,35,MATCH($B$3,Dati_grezzi!$A$1:$D$1,0)) -> 4.9 | G39: =IF(OR(A39<$E$5,A39>$F$5),"YES","NO") -> NO | H39: =(A39-AVERAGE(INDEX(Dati_grezzi!$A$2:$D$151,0,MATCH($B$3,Dati_grezzi!$A$1:$D$1,0))))/_xlfn.SINGLE(STDEV(INDEX(Dati_grezzi!$A$2:$D$151,0,MATCH($B$3,Dati_grezzi!$A$1:$D$1,0)))) -> -1.1392005 | I39: =IF(ABS(H39)>3,"YES","NO") -> NO
A40: =INDEX(Dati_grezzi!$A$2:$D$151,36,MATCH($B$3,Dati_grezzi!$A$1:$D$1,0)) -> 5 | G40: =IF(OR(A40<$E$5,A40>$F$5),"YES","NO") -> NO | H40: =(A40-AVERAGE(INDEX(Dati_grezzi!$A$2:$D$151,0,MATCH($B$3,Dati_grezzi!$A$1:$D$1,0))))/_xlfn.SINGLE(STDEV(INDEX(Dati_grezzi!$A$2:$D$151,0,MATCH($B$3,Dati_grezzi!$A$1:$D$1,0)))) -> -1.0184372 | I40: =IF(ABS(H40)>3,"YES","NO") -> NO
A41: =INDEX(Dati_grezzi!$A$2:$D$151,37,MATCH($B$3,Dati_grezzi!$A$1:$D$1,0)) -> 5.5 | G41: =IF(OR(A41<$E$5,A41>$F$5),"YES","NO") -> NO | H41: =(A41-AVERAGE(INDEX(Dati_grezzi!$A$2:$D$151,0,MATCH($B$3,Dati_grezzi!$A$1:$D$1,0))))/_xlfn.SINGLE(STDEV(INDEX(Dati_grezzi!$A$2:$D$151,0,MATCH($B$3,Dati_grezzi!$A$1:$D$1,0)))) -> -0.41462067 | I41: =IF(ABS(H41)>3,"YES","NO") -> NO
...

Sheet Chi Quadro
A2: Lunghezza del petalo
A3: Somma di Contatore | B3: Etichette di colonna
A4: Etichette di riga | B4: Alto | C4: Basso | D4: Medio | E4: Totale complessivo
A5: setosa | C5: 50 | E5: 50
A6: versicolor | B6: 2 | D6: 48 | E6: 50
A7: virginica | B7: 44 | D7: 6 | E7: 50
A8: Totale complessivo | B8: 46 | C8: 50 | D8: 54 | E8: 150
A10: Valori attesi
A11: Setosa | B11: Versicolor | C11: Virginica
A12: =$E5*B$8/$E$8 -> 15.333333 | B12: =$E5*C$8/$E$8 -> 16.666667 | C12: =$E5*D$8/$E$8 -> 18
A13: =$E6*B$8/$E$8 -> 15.333333 | B13: =$E6*C$8/$E$8 -> 16.666667 | C13: =$E6*D$8/$E$8 -> 18
A14: =$E7*B$8/$E$8 -> 15.333333 | B14: =$E7*C$8/$E$8 -> 16.666667 | C14: =$E7*D$8/$E$8 -> 18
A17: Valori attesi, li calcoliamo come: ((valore riga)*(totale colonna))/(totale complessivo)
A19: Quindi, applichiamo il chi quadro
A21: =_xlfn.CHISQ.TEST(B5:D7,A12:C14) -> 5.6942709e-40
A22: la nostra H0 era che le due sono indipendenti, è vero?

Sheet Consegna
A1: Consegna
A3: Rispondi in modo conciso e incolla screenshot dei grafici.
A5: Q1) Quale coppia di feature separa meglio le classi?
A6: Q2) Dove vedi sovrapposizioni tra classi?
A7: Q3) Hai trovato outlier? Sono errori o informazione?
A8: Q4) Z-score vs Min-Max: quando useresti l’uno o l’altro?
A9: Q5) Perché è importante standardizzare prima di alcuni modelli?
